Workbook

Sheet README
A1: Corporate Travel Programme Analytics — Synthetic Dataset
A2: Dataset purpose | B2: Portfolio project for analysing corporate travel cost, policy compliance, supplier usage, trip changes/cancellations, service performance and traveller experience using Excel, SQL and Power BI/Tableau.
A3: Period | B3: 1 May 2026 – 31 July 2026
A4: Travellers | B4: 160
A5: Trips | B5: 582
A6: Change events | B6: 100
A7: Cancellation events | B7: 36
A8: Data status | B8: 100% synthetic. Real supplier brand names are used only to make the fictional scenario easier to understand. Preferred-supplier status and all performance/cost data are fictional.
A10: BUSINESS PROBLEM
A11: Primary problem | B11: Corporate travel programmes can lose money through late booking, off-channel booking, itinerary changes, cancellations and weak preferred-supplier adoption, while service issues can reduce traveller satisfaction.
A12: Objective 1 | B12: Identify where travel spend is concentrated and which booking behaviours are associated with higher cost.
A13: Objective 2 | B13: Measure policy compliance and identify departments, offices or channels with higher non-compliance.
A14: Objective 3 | B14: Assess preferred airline/hotel usage and identify opportunities to consolidate spend.
A15: Objective 4 | B15: Measure the cost impact of itinerary changes and cancellations, including how much cancelled spend is recovered through refunds.
A16: Objective 5 | B16: Compare TMC/OBT service performance against targets and investigate links with traveller satisfaction.
A17: Objective 6 | B17: Quantify travel-related CO2 patterns and identify high-emission routes or travel behaviours.
A19: KEY DEFINITIONS
A20: One row in Trips | B20: One complete business trip from the traveller's home office to a destination and back. departure_date and return_date define the trip period.
A21: Trip purpose | B21: Reason for travel: Client meeting, Project work, Internal meeting, Training, Conference / Event, Team building, Recruitment / Interview or Other.
A22: Booking lead time | B22: Days between booking_date and departure_date. In this synthetic scenario, late bookings tend to cost more.
A23: Booking channel | B23: Online Booking Tool = preferred self-service channel; TMC Assisted = supported by a travel management company; Direct Supplier = booked directly with airline/hotel; Other = non-standard channel.
A24: Policy compliant | B24: Yes/No indicator showing whether the trip followed the fictional travel policy. Very late and off-channel bookings are more likely to be non-compliant.
A25: Changed | B25: Yes if at least one detailed event exists in Trip Changes.
A26: Cancelled | B26: Yes if a detailed cancellation event exists in Trip Cancellations.
A27: Change cost | B27: Additional cost created by itinerary amendments/rebooking. A trip can have more than one change event.
A28: Cancellation fee | B28: Fee charged when a trip is cancelled.
A29: Refund received | B29: Money recovered after cancellation for unused travel/hotel value.
A30: Original trip cost | B30: Air/rail + hotel + ground transport before any changes, cancellation fees or refunds.
A31: Final trip cost | B31: Original trip cost + change costs + cancellation fees - refunds received.
... A40: CO2 kg | B40: Illustrative estimate only: air = 0.15 kg per passenger-km; rail = 0.04 kg per passenger-km. Not suitable for formal emissions reporting.
A42: TABLE GUIDE
A43: Trips | B43: Fact table: one row per complete business trip. Summary change/cancellation costs are formula-driven from the event tables.
A44: Travellers | B44: Fictional traveller dimension with home office, department and grade.
A45: Airlines | B45: Airline dimension using real brand names; preferred status is fictional.
A46: Hotels | B46: Hotel dimension using real brand names; preferred status is fictional.
A47: Trip Changes | B47: Event table: one row per itinerary-change event. Multiple rows can relate to one trip.
A48: Trip Cancellations | B48: Event table: one row per cancellation event, including cancellation fee and refund received.
A49: Service Performance | B49: Monthly fictional target vs actual TMC and online-booking metrics.
A50: Traveller Feedback | B50: Short post-trip survey linked to Trips by trip_id. Only a minority of travellers submit feedback.
A51: Feedback response rate | B51: 41.1% in this synthetic dataset. This is intentionally below 50% to reflect low survey participation.
...

Sheet Executive Summary
A1: EXECUTIVE SUMMARY
A2: Corporate travel programme performance | May-July 2026
A6: Total Trips: | B6: Total Spend: | C6: Avg Trip Cost: | D6: Policy Compliance: | E6: Changed Trips: | F6: Cancelled Trips: | G6: Avg Traveller Rating (1-5): | H6: Total CO₂ Emissions, kg:
A7: ='Spend & Booking Analysis'!A7 -> 582 | B7: ='Spend & Booking Analysis'!B7 -> 580808.63 | C7: ='Spend & Booking Analysis'!C7 -> 997.95297 | D7: ='Compliance Analysis'!A7 -> 0.43127148 | E7: =Changes_Cancellations_Analysis!B7 -> 0.1443299 | F7: =Changes_Cancellations_Analysis!E7 -> 0.06185567 | G7: ='Feedback & SP Analysis'!C7 -> 4.209205 | H7: =Sustainability_Analysis!A7 -> 356259.4
A11: Key Findings:
A12: 1. July had the highest travel spend and average trip cost.
A14: 2. International trips cost more than twice as much as domestic trips on average.
A16: 3. Earlier booking was generally associated with lower airfare costs.
A18: 4. Overall calculated policy compliance was 43.1%; hotel-rate violations and off-channel booking were the main issues.
A20: 5. Preferred supplier adoption remained strong at 94.1% for airlines and 88.6% for hotels.
A22: 6. 14.4% of trips were changed; flight rebooking accounted for about 53% of change costs.
A24: 7. Traveller satisfaction remained strong at 4.21/5, but TMC SLA and CSAT declined over the period.
A26: 8. Air travel accounted for 99.3% of estimated CO₂ emissions.
A29: Recommendations:
A30: 1. Introduce destination- or market-based hotel caps instead of one flat rate.
A32: 2. Encourage earlier booking where business needs allow.
... A40: 6. Consider rail substitution and CO₂ impact when reviewing suitable short-haul routes.

Sheet Policy Reference
A1: rule_area | B1: condition | C1: policy_rule
A2: Booking Channel | B2: All trips | C2: Use Online Booking Tool or TMC Assisted
A3: Hotel Rate | B3: UK / US / high-cost markets | C3: Max £220 per night
A4: Hotel Rate | B4: Standard-cost markets | C4: Max £180 per night
A5: Air Cabin | B5: Air travel | C5: Economy
A6: Rail Class | B6: Rail travel | C6: Standard / 2nd class
A7: Advance Booking | B7: All trips | C7: Recommended 14+ days; KPI only, not automatic non-compliance

Sheet Trips_Raw
A1: trip_id | B1: employee_id | C1: home_office | D1: department | E1: grade | F1: trip_purpose | G1: booking_date | H1: departure_date | I1: return_date | J1: travel_month | K1: origin | L1: destination | M1: trip_type | N1: travel_mode | O1: distance_km | P1: booking_lead_days | Q1: booking_channel | R1: airline_id | S1: hotel_id | T1: airfare_gbp | U1: rail_cost_gbp | V1: hotel_nights | W1: hotel_cost_gbp | X1: ground_transport_gbp | Y1: original_trip_cost_gbp | Z1: changed | AA1: cancelled | AB1: total_change_cost_gbp | AC1: total_cancellation_fee_gbp | AD1: refund_received_gbp | AE1: final_trip_cost_gbp | AF1: policy_compliant | AG1: csat_score | AH1: co2_kg | AI1: feedback_submitted
A2: T00001 | B2: E0001 | C2: Aberdeen | D2: Technology | E2: Senior Manager | F2: Client meeting | G2: 46176 | H2: 46189 | I2: 46192 | J2: 2026-06 | K2: Aberdeen | L2: Manchester | M2: Domestic | N2: Rail | O2: 1010 | P2: 13 | Q2: Online Booking Tool | S2: H06 | T2: 0 | U2: 182.55 | V2: 2 | W2: 327.67 | X2: 56.62 | Y2: 566.84 | Z2: No | AA2: No | AB2: =SUMIF('Trip Changes'!$B:$B,A2,'Trip Changes'!$E:$E) -> 0 | AC2: =SUMIF('Trip Cancellations'!$B:$B,A2,'Trip Cancellations'!$E:$E) -> 0 | AD2: =SUMIF('Trip Cancellations'!$B:$B,A2,'Trip Cancellations'!$F:$F) -> 0 | AE2: =Y2+AB2+AC2-AD2 -> 566.84 | AF2: Yes | AG2: 5 | AH2: 40.4 | AI2: Yes
A3: T00002 | B3: E0001 | C3: Aberdeen | D3: Technology | E3: Senior Manager | F3: Client meeting | G3: 46224 | H3: 46226 | I3: 46230 | J3: 2026-07 | K3: Aberdeen | L3: Frankfurt | M3: International | N3: Air | O3: 1390 | P3: 2 | Q3: Online Booking Tool | R3: A01 | S3: H02 | T3: 480.08 | U3: 0 | V3: 3 | W3: 561.27 | X3: 59 | Y3: 1100.35 | Z3: No | AA3: No | AB3: =SUMIF('Trip Changes'!$B:$B,A3,'Trip Changes'!$E:$E) -> 0 | AC3: =SUMIF('Trip Cancellations'!$B:$B,A3,'Trip Cancellations'!$E:$E) -> 0 | AD3: =SUMIF('Trip Cancellations'!$B:$B,A3,'Trip Cancellations'!$F:$F) -> 0 | AE3: =Y3+AB3+AC3-AD3 -> 1100.35 | AF3: Yes | AG3: 4 | AH3: 208.5 | AI3: No
A4: T00003 | B4: E0001 | C4: Aberdeen | D4: Technology | E4: Senior Manager | F4: Internal meeting | G4: 46169 | H4: 46178 | I4: 46182 | J4: 2026-06 | K4: Aberdeen | L4: Milan | M4: International | N4: Air | O4: 1900 | P4: 9 | Q4: TMC Assisted | R4: A05 | S4: H02 | T4: 416.18 | U4: 0 | V4: 3 | W4: 637.56 | X4: 140.94 | Y4: 1194.68 | Z4: No | AA4: No | AB4: =SUMIF('Trip Changes'!$B:$B,A4,'Trip Changes'!$E:$E) -> 0 | AC4: =SUMIF('Trip Cancellations'!$B:$B,A4,'Trip Cancellations'!$E:$E) -> 0 | AD4: =SUMIF('Trip Cancellations'!$B:$B,A4,'Trip Cancellations'!$F:$F) -> 0 | AE4: =Y4+AB4+AC4-AD4 -> 1194.68 | AF4: Yes | AG4: 5 | AH4: 285 | AI4: Yes
A5: T00004 | B5: E0001 | C5: Aberdeen | D5: Technology | E5: Senior Manager | F5: Project work | G5: 46139 | H5: 46153 | I5: 46155 | J5: 2026-05 | K5: Aberdeen | L5: Frankfurt | M5: International | N5: Air | O5: 1676 | P5: 14 | Q5: Online Booking Tool | R5: A01 | S5: H01 | T5: 261.15 | U5: 0 | V5: 1 | W5: 267.93 | X5: 132.51 | Y5: 661.59 | Z5: No | AA5: No | AB5: =SUMIF('Trip Changes'!$B:$B,A5,'Trip Changes'!$E:$E) -> 0 | AC5: =SUMIF('Trip Cancellations'!$B:$B,A5,'Trip Cancellations'!$E:$E) -> 0 | AD5: =SUMIF('Trip Cancellations'!$B:$B,A5,'Trip Cancellations'!$F:$F) -> 0 | AE5: =Y5+AB5+AC5-AD5 -> 661.59 | AF5: Yes | AG5: 4 | AH5: 251.4 | AI5: No
A6: T00005 | B6: E0002 | C6: Reading | D6: Audit & Assurance | E6: Manager | F6: Conference / Event | G6: 46114 | H6: 46146 | I6: 46149 | J6: 2026-05 | K6: Reading | L6: Berlin | M6: International | N6: Air | O6: 1146 | P6: 32 | Q6: TMC Assisted | R6: A04 | S6: H04 | T6: 502.93 | U6: 0 | V6: 2 | W6: 277.1 | X6: 65.55 | Y6: 845.58 | Z6: No | AA6: No | AB6: =SUMIF('Trip Changes'!$B:$B,A6,'Trip Changes'!$E:$E) -> 0 | AC6: =SUMIF('Trip Cancellations'!$B:$B,A6,'Trip Cancellations'!$E:$E) -> 0 | AD6: =SUMIF('Trip Cancellations'!$B:$B,A6,'Trip Cancellations'!$F:$F) -> 0 | AE6: =Y6+AB6+AC6-AD6 -> 845.58 | AF6: Yes | AG6: 5 | AH6: 171.9 | AI6: No
A7: T00006 | B7: E0002 | C7: Reading | D7: Audit & Assurance | E7: Manager | F7: Client meeting | G7: 46153 | H7: 46170 | I7: 46174 | J7: 2026-05 | K7: Reading | L7: Zurich | M7: International | N7: Air | O7: 2472 | P7: 17 | Q7: Online Booking Tool | R7: A02 | S7: H02 | T7: 150 | U7: 0 | V7: 3 | W7: 457.88 | X7: 45.91 | Y7: 653.79 | Z7: No | AA7: No | AB7: =SUMIF('Trip Changes'!$B:$B,A7,'Trip Changes'!$E:$E) -> 0 | AC7: =SUMIF('Trip Cancellations'!$B:$B,A7,'Trip Cancellations'!$E:$E) -> 0 | AD7: =SUMIF('Trip Cancellations'!$B:$B,A7,'Trip Cancellations'!$F:$F) -> 0 | AE7: =Y7+AB7+AC7-AD7 -> 653.79 | AF7: Yes | AG7: 5 | AH7: 370.8 | AI7: No
A8: T00007 | B8: E0002 | C8: Reading | D8: Audit & Assurance | E8: Manager | F8: Team building | G8: 46208 | H8: 46226 | I8: 46231 | J8: 2026-07 | K8: Reading | L8: Dubai | M8: International | N8: Air | O8: 16462 | P8: 18 | Q8: TMC Assisted | R8: A01 | S8: H02 | T8: 1520.77 | U8: 0 | V8: 4 | W8: 1033.5 | X8: 73.48 | Y8: 2627.75 | Z8: No | AA8: No | AB8: =SUMIF('Trip Changes'!$B:$B,A8,'Trip Changes'!$E:$E) -> 0 | AC8: =SUMIF('Trip Cancellations'!$B:$B,A8,'Trip Cancellations'!$E:$E) -> 0 | AD8: =SUMIF('Trip Cancellations'!$B:$B,A8,'Trip Cancellations'!$F:$F) -> 0 | AE8: =Y8+AB8+AC8-AD8 -> 2627.75 | AF8: No | AG8: 5 | AH8: 2469.3 | AI8: No
A9: T00008 | B9: E0002 | C9: Reading | D9: Audit & Assurance | E9: Manager | F9: Recruitment / Interview | G9: 46193 | H9: 46203 | I9: 46205 | J9: 2026-06 | K9: Reading | L9: London | M9: Domestic | N9: Rail | O9: 512 | P9: 10 | Q9: Online Booking Tool | S9: H02 | T9: 0 | U9: 200.83 | V9: 1 | W9: 133.25 | X9: 26.45 | Y9: 360.53 | Z9: No | AA9: No | AB9: =SUMIF('Trip Changes'!$B:$B,A9,'Trip Changes'!$E:$E) -> 0 | AC9: =SUMIF('Trip Cancellations'!$B:$B,A9,'Trip Cancellations'!$E:$E) -> 0 | AD9: =SUMIF('Trip Cancellations'!$B:$B,A9,'Trip Cancellations'!$F:$F) -> 0 | AE9: =Y9+AB9+AC9-AD9 -> 360.53 | AF9: Yes | AG9: 4 | AH9: 20.5 | AI9: No
A10: T00009 | B10: E0003 | C10: Manchester | D10: Technology | E10: Senior Manager | F10: Recruitment / Interview | G10: 46160 | H10: 46184 | I10: 46186 | J10: 2026-06 | K10: Manchester | L10: New York | M10: International | N10: Air | O10: 12978 | P10: 24 | Q10: Online Booking Tool | R10: A07 | S10: H03 | T10: 520 | U10: 0 | V10: 1 | W10: 208.72 | X10: 74.62 | Y10: 803.34 | Z10: No | AA10: No | AB10: =SUMIF('Trip Changes'!$B:$B,A10,'Trip Changes'!$E:$E) -> 0 | AC10: =SUMIF('Trip Cancellations'!$B:$B,A10,'Trip Cancellations'!$E:$E) -> 0 | AD10: =SUMIF('Trip Cancellations'!$B:$B,A10,'Trip Cancellations'!$F:$F) -> 0 | AE10: =Y10+AB10+AC10-AD10 -> 803.34 | AF10: Yes | AG10: 5 | AH10: 1946.7 | AI10: No
A11: T00010 | B11: E0003 | C11: Manchester | D11: Technology | E11: Senior Manager | F11: Training | G11: 46212 | H11: 46224 | I11: 46228 | J11: 2026-07 | K11: Manchester | L11: New York | M11: International | N11: Air | O11: 11812 | P11: 12 | Q11: TMC Assisted | R11: A07 | S11: H05 | T11: 1607.82 | U11: 0 | V11: 3 | W11: 565.67 | X11: 94.45 | Y11: 2267.94 | Z11: No | AA11: Yes | AB11: =SUMIF('Trip Changes'!$B:$B,A11,'Trip Changes'!$E:$E) -> 0 | AC11: =SUMIF('Trip Cancellations'!$B:$B,A11,'Trip Cancellations'!$E:$E) -> 176.35 | AD11: =SUMIF('Trip Cancellations'!$B:$B,A11,'Trip Cancellations'!$F:$F) -> 1086.74 | AE11: =Y11+AB11+AC11-AD11 -> 1357.55 | AF11: Yes | AG11: 3 | AH11: 1771.8 | AI11: Yes
A12: T00011 | B12: E0004 | C12: Birmingham | D12: Corporate Functions | E12: Manager | F12: Internal meeting | G12: 46204 | H12: 46213 | I12: 46216 | J12: 2026-07 | K12: Birmingham | L12: London | M12: Domestic | N12: Rail | O12: 324 | P12: 9 | Q12: Online Booking Tool | S12: H07 | T12: 0 | U12: 171.23 | V12: 2 | W12: 343.72 | X12: 105.02 | Y12: 619.97 | Z12: No | AA12: No | AB12: =SUMIF('Trip Changes'!$B:$B,A12,'Trip Changes'!$E:$E) -> 0 | AC12: =SUMIF('Trip Cancellations'!$B:$B,A12,'Trip Cancellations'!$E:$E) -> 0 | AD12: =SUMIF('Trip Cancellations'!$B:$B,A12,'Trip Cancellations'!$F:$F) -> 0 | AE12: =Y12+AB12+AC12-AD12 -> 619.97 | AF12: Yes | AG12: 4 | AH12: 13 | AI12: No
A13: T00012 | B13: E0004 | C13: Birmingham | D13: Corporate Functions | E13: Manager | F13: Team building | G13: 46186 | H13: 46200 | I13: 46204 | J13: 2026-06 | K13: Birmingham | L13: Chicago | M13: International | N13: Air | O13: 10018 | P13: 14 | Q13: Online Booking Tool | R13: A01 | S13: H04 | T13: 696.01 | U13: 0 | V13: 3 | W13: 521.16 | X13: 112.08 | Y13: 1329.25 | Z13: No | AA13: No | AB13: =SUMIF('Trip Changes'!$B:$B,A13,'Trip Changes'!$E:$E) -> 0 | AC13: =SUMIF('Trip Cancellations'!$B:$B,A13,'Trip Cancellations'!$E:$E) -> 0 | AD13: =SUMIF('Trip Cancellations'!$B:$B,A13,'Trip Cancellations'!$F:$F) -> 0 | AE13: =Y13+AB13+AC13-AD13 -> 1329.25 | AF13: Yes | AG13: 3 | AH13: 1502.7 | AI13: Yes
A14: T00013 | B14: E0004 | C14: Birmingham | D14: Corporate Functions | E14: Manager | F14: Project work | G14: 46167 | H14: 46187 | I14: 46189 | J14: 2026-06 | K14: Birmingham | L14: Dublin | M14: International | N14: Air | O14: 2196 | P14: 20 | Q14: Online Booking Tool | R14: A10 | S14: H02 | T14: 538.24 | U14: 0 | V14: 1 | W14: 124.82 | X14: 114.97 | Y14: 778.03 | Z14: No | AA14: No | AB14: =SUMIF('Trip Changes'!$B:$B,A14,'Trip Changes'!$E:$E) -> 0 | AC14: =SUMIF('Trip Cancellations'!$B:$B,A14,'Trip Cancellations'!$E:$E) -> 0 | AD14: =SUMIF('Trip Cancellations'!$B:$B,A14,'Trip Cancellations'!$F:$F) -> 0 | AE14: =Y14+AB14+AC14-AD14 -> 778.03 | AF14: Yes | AG14: 4 | AH14: 329.4 | AI14: Yes
A15: T00014 | B15: E0005 | C15: Glasgow | D15: Risk Advisory | E15: Partner | F15: Internal meeting | G15: 46171 | H15: 46175 | I15: 46178 | J15: 2026-06 | K15: Glasgow | L15: Birmingham | M15: Domestic | N15: Rail | O15: 466 | P15: 4 | Q15: TMC Assisted | S15: H06 | T15: 0 | U15: 214.9 | V15: 2 | W15: 352.41 | X15: 66.37 | Y15: 633.68 | Z15: No | AA15: No | AB15: =SUMIF('Trip Changes'!$B:$B,A15,'Trip Changes'!$E:$E) -> 0 | AC15: =SUMIF('Trip Cancellations'!$B:$B,A15,'Trip Cancellations'!$E:$E) -> 0 | AD15: =SUMIF('Trip Cancellations'!$B:$B,A15,'Trip Cancellations'!$F:$F) -> 0 | AE15: =Y15+AB15+AC15-AD15 -> 633.68 | AF15: Yes | AG15: 4 | AH15: 18.6 | AI15: No
A16: T00015 | B16: E0005 | C16: Glasgow | D16: Risk Advisory | E16: Partner | F16: Training | G16: 46129 | H16: 46148 | I16: 46150 | J16: 2026-05 | K16: Glasgow | L16: Frankfurt | M16: International | N16: Air | O16: 3248 | P16: 19 | Q16: Other | R16: A04 | S16: H04 | T16: 495.08 | U16: 0 | V16: 1 | W16: 170.56 | X16: 81.71 | Y16: 747.35 | Z16: No | AA16: Yes | AB16: =SUMIF('Trip Changes'!$B:$B,A16,'Trip Changes'!$E:$E) -> 0 | AC16: =SUMIF('Trip Cancellations'!$B:$B,A16,'Trip Cancellations'!$E:$E) -> 56.37 | AD16: =SUMIF('Trip Cancellations'!$B:$B,A16,'Trip Cancellations'!$F:$F) -> 166.41 | AE16: =Y16+AB16+AC16-AD16 -> 637.31 | AF16: Yes | AG16: 3 | AH16: 487.2 | AI16: No
A17: T00016 | B17: E0005 | C17: Glasgow | D17: Risk Advisory | E17: Partner | F17: Training | G17: 46133 | H17: 46143 | I17: 46146 | J17: 2026-05 | K17: Glasgow | L17: Munich | M17: International | N17: Air | O17: 1008 | P17: 10 | Q17: Online Booking Tool | R17: A01 | S17: H05 | T17: 564.55 | U17: 0 | V17: 2 | W17: 314.65 | X17: 58.08 | Y17: 937.28 | Z17: Yes | AA17: No | AB17: =SUMIF('Trip Changes'!$B:$B,A17,'Trip Changes'!$E:$E) -> 323.4 | AC17: =SUMIF('Trip Cancellations'!$B:$B,A17,'Trip Cancellations'!$E:$E) -> 0 | AD17: =SUMIF('Trip Cancellations'!$B:$B,A17,'Trip Cancellations'!$F:$F) -> 0 | AE17: =Y17+AB17+AC17-AD17 -> 1260.68 | AF17: Yes | AG17: 4 | AH17: 151.2 | AI17: Yes
A18: T00017 | B18: E0005 | C18: Glasgow | D18: Risk Advisory | E18: Partner | F18: Client meeting | G18: 46219 | H18: 46234 | I18: 46236 | J18: 2026-07 | K18: Glasgow | L18: Berlin | M18: International | N18: Air | O18: 1742 | P18: 15 | Q18: Online Booking Tool | R18: A04 | S18: H04 | T18: 428.63 | U18: 0 | V18: 1 | W18: 221.58 | X18: 108.19 | Y18: 758.4 | Z18: No | AA18: No | AB18: =SUMIF('Trip Changes'!$B:$B,A18,'Trip Changes'!$E:$E) -> 0 | AC18: =SUMIF('Trip Cancellations'!$B:$B,A18,'Trip Cancellations'!$E:$E) -> 0 | AD18: =SUMIF('Trip Cancellations'!$B:$B,A18,'Trip Cancellations'!$F:$F) -> 0 | AE18: =Y18+AB18+AC18-AD18 -> 758.4 | AF18: Yes | AG18: 5 | AH18: 261.3 | AI18: No
A19: T00018 | B19: E0005 | C19: Glasgow | D19: Risk Advisory | E19: Partner | F19: Project work | G19: 46167 | H19: 46201 | I19: 46203 | J19: 2026-06 | K19: Glasgow | L19: London | M19: Domestic | N19: Rail | O19: 926 | P19: 34 | Q19: TMC Assisted | S19: H06 | T19: 0 | U19: 183.42 | V19: 1 | W19: 173.9 | X19: 23.93 | Y19: 381.25 | Z19: No | AA19: No | AB19: =SUMIF('Trip Changes'!$B:$B,A19,'Trip Changes'!$E:$E) -> 0 | AC19: =SUMIF('Trip Cancellations'!$B:$B,A19,'Trip Cancellations'!$E:$E) -> 0 | AD19: =SUMIF('Trip Cancellations'!$B:$B,A19,'Trip Cancellations'!$F:$F) -> 0 | AE19: =Y19+AB19+AC19-AD19 -> 381.25 | AF19: Yes | AG19: 4 | AH19: 37 | AI19: Yes
A20: T00019 | B20: E0006 | C20: London | D20: Technology | E20: Manager | F20: Client meeting | G20: 46163 | H20: 46178 | I20: 46180 | J20: 2026-06 | K20: London | L20: Zurich | M20: International | N20: Air | O20: 3392 | P20: 15 | Q20: Online Booking Tool | R20: A04 | S20: H02 | T20: 404.59 | U20: 0 | V20: 1 | W20: 104.98 | X20: 120.09 | Y20: 629.66 | Z20: No | AA20: No | AB20: =SUMIF('Trip Changes'!$B:$B,A20,'Trip Changes'!$E:$E) -> 0 | AC20: =SUMIF('Trip Cancellations'!$B:$B,A20,'Trip Cancellations'!$E:$E) -> 0 | AD20: =SUMIF('Trip Cancellations'!$B:$B,A20,'Trip Cancellations'!$F:$F) -> 0 | AE20: =Y20+AB20+AC20-AD20 -> 629.66 | AF20: Yes | AG20: 4 | AH20: 508.8 | AI20: No
A21: T00020 | B21: E0006 | C21: London | D21: Technology | E21: Manager | F21: Recruitment / Interview | G21: 46163 | H21: 46175 | I21: 46179 | J21: 2026-06 | K21: London | L21: Copenhagen | M21: International | N21: Air | O21: 3324 | P21: 12 | Q21: Direct Supplier | R21: A05 | S21: H05 | T21: 425.02 | U21: 0 | V21: 3 | W21: 526.8 | X21: 74.85 | Y21: 1026.67 | Z21: No | AA21: No | AB21: =SUMIF('Trip Changes'!$B:$B,A21,'Trip Changes'!$E:$E) -> 0 | AC21: =SUMIF('Trip Cancellations'!$B:$B,A21,'Trip Cancellations'!$E:$E) -> 0 | AD21: =SUMIF('Trip Cancellations'!$B:$B,A21,'Trip Cancellations'!$F:$F) -> 0 | AE21: =Y21+AB21+AC21-AD21 -> 1026.67 | AF21: Yes | AG21: 4 | AH21: 498.6 | AI21: No
A22: T00021 | B22: E0006 | C22: London | D22: Technology | E22: Manager | F22: Client meeting | G22: 46166 | H22: 46191 | I22: 46195 | J22: 2026-06 | K22: London | L22: Zurich | M22: International | N22: Air | O22: 1578 | P22: 25 | Q22: TMC Assisted | R22: A01 | S22: H03 | T22: 262.28 | U22: 0 | V22: 3 | W22: 440.34 | X22: 97.7 | Y22: 800.32 | Z22: No | AA22: No | AB22: =SUMIF('Trip Changes'!$B:$B,A22,'Trip Changes'!$E:$E) -> 0 | AC22: =SUMIF('Trip Cancellations'!$B:$B,A22,'Trip Cancellations'!$E:$E) -> 0 | AD22: =SUMIF('Trip Cancellations'!$B:$B,A22,'Trip Cancellations'!$F:$F) -> 0 | AE22: =Y22+AB22+AC22-AD22 -> 800.32 | AF22: Yes | AG22: 5 | AH22: 236.7 | AI22: Yes
A23: T00022 | B23: E0007 | C23: Newcastle | D23: Risk Advisory | E23: Manager | F23: Client meeting | G23: 46226 | H23: 46227 | I23: 46229 | J23: 2026-07 | K23: Newcastle | L23: Dublin | M23: International | N23: Air | O23: 1762 | P23: 1 | Q23: TMC Assisted | R23: A10 | S23: H04 | T23: 411.87 | U23: 0 | V23: 1 | W23: 92.01 | X23: 93.12 | Y23: 597 | Z23: Yes | AA23: No | AB23: =SUMIF('Trip Changes'!$B:$B,A23,'Trip Changes'!$E:$E) -> 70.28 | AC23: =SUMIF('Trip Cancellations'!$B:$B,A23,'Trip Cancellations'!$E:$E) -> 0 | AD23: =SUMIF('Trip Cancellations'!$B:$B,A23,'Trip Cancellations'!$F:$F) -> 0 | AE23: =Y23+AB23+AC23-AD23 -> 667.28 | AF23: Yes | AG23: 5 | AH23: 264.3 | AI23: No
A24: T00023 | B24: E0007 | C24: Newcastle | D24: Risk Advisory | E24: Manager | F24: Project work | G24: 46135 | H24: 46148 | I24: 46150 | J24: 2026-05 | K24: Newcastle | L24: Manchester | M24: Domestic | N24: Rail | O24: 756 | P24: 13 | Q24: Online Booking Tool | S24: H02 | T24: 0 | U24: 203.34 | V24: 1 | W24: 162.11 | X24: 37.13 | Y24: 402.58 | Z24: Yes | AA24: No | AB24: =SUMIF('Trip Changes'!$B:$B,A24,'Trip Changes'!$E:$E) -> 147.88 | AC24: =SUMIF('Trip Cancellations'!$B:$B,A24,'Trip Cancellations'!$E:$E) -> 0 | AD24: =SUMIF('Trip Cancellations'!$B:$B,A24,'Trip Cancellations'!$F:$F) -> 0 | AE24: =Y24+AB24+AC24-AD24 -> 550.46 | AF24: Yes | AG24: 4 | AH24: 30.2 | AI24: Yes
A25: T00024 | B25: E0007 | C25: Newcastle | D25: Risk Advisory | E25: Manager | F25: Client meeting | G25: 46125 | H25: 46146 | I25: 46152 | J25: 2026-05 | K25: Newcastle | L25: Hong Kong | M25: International | N25: Air | O25: 14602 | P25: 21 | Q25: Online Booking Tool | R25: A01 | S25: H01 | T25: 1301.17 | U25: 0 | V25: 5 | W25: 671.37 | X25: 122.79 | Y25: 2095.33 | Z25: No | AA25: No | AB25: =SUMIF('Trip Changes'!$B:$B,A25,'Trip Changes'!$E:$E) -> 0 | AC25: =SUMIF('Trip Cancellations'!$B:$B,A25,'Trip Cancellations'!$E:$E) -> 0 | AD25: =SUMIF('Trip Cancellations'!$B:$B,A25,'Trip Cancellations'!$F:$F) -> 0 | AE25: =Y25+AB25+AC25-AD25 -> 2095.33 | AF25: Yes | AG25: 3 | AH25: 2190.3 | AI25: No
A26: T00025 | B26: E0007 | C26: Newcastle | D26: Risk Advisory | E26: Manager | F26: Internal meeting | G26: 46214 | H26: 46222 | I26: 46225 | J26: 2026-07 | K26: Newcastle | L26: Amsterdam | M26: International | N26: Air | O26: 1608 | P26: 8 | Q26: Online Booking Tool | R26: A01 | S26: H03 | T26: 449.88 | U26: 0 | V26: 2 | W26: 392.67 | X26: 110.06 | Y26: 952.61 | Z26: No | AA26: No | AB26: =SUMIF('Trip Changes'!$B:$B,A26,'Trip Changes'!$E:$E) -> 0 | AC26: =SUMIF('Trip Cancellations'!$B:$B,A26,'Trip Cancellations'!$E:$E) -> 0 | AD26: =SUMIF('Trip Cancellations'!$B:$B,A26,'Trip Cancellations'!$F:$F) -> 0 | AE26: =Y26+AB26+AC26-AD26 -> 952.61 | AF26: Yes | AG26: 4 | AH26: 241.2 | AI26: No
A27: T00026 | B27: E0007 | C27: Newcastle | D27: Risk Advisory | E27: Manager | F27: Internal meeting | G27: 46189 | H27: 46195 | I27: 46197 | J27: 2026-06 | K27: Newcastle | L27: Brussels | M27: International | N27: Air | O27: 2688 | P27: 6 | Q27: Online Booking Tool | R27: A04 | S27: H04 | T27: 639.1 | U27: 0 | V27: 1 | W27: 231.27 | X27: 77.78 | Y27: 948.15 | Z27: No | AA27: Yes | AB27: =SUMIF('Trip Changes'!$B:$B,A27,'Trip Changes'!$E:$E) -> 0 | AC27: =SUMIF('Trip Cancellations'!$B:$B,A27,'Trip Cancellations'!$E:$E) -> 87.4 | AD27: =SUMIF('Trip Cancellations'!$B:$B,A27,'Trip Cancellations'!$F:$F) -> 783.33 | AE27: =Y27+AB27+AC27-AD27 -> 252.22 | AF27: Yes | AG27: 3 | AH27: 403.2 | AI27: Yes
A28: T00027 | B28: E0008 | C28: Birmingham | D28: Tax & Legal | E28: Manager | F28: Client meeting | G28: 46152 | H28: 46189 | I28: 46190 | J28: 2026-06 | K28: Birmingham | L28: London | M28: Domestic | N28: Rail | O28: 1206 | P28: 37 | Q28: Direct Supplier | T28: 0 | U28: 132.82 | V28: 0 | W28: 0 | X28: 66.98 | Y28: 199.8 | Z28: No | AA28: No | AB28: =SUMIF('Trip Changes'!$B:$B,A28,'Trip Changes'!$E:$E) -> 0 | AC28: =SUMIF('Trip Cancellations'!$B:$B,A28,'Trip Cancellations'!$E:$E) -> 0 | AD28: =SUMIF('Trip Cancellations'!$B:$B,A28,'Trip Cancellations'!$F:$F) -> 0 | AE28: =Y28+AB28+AC28-AD28 -> 199.8 | AF28: No | AG28: 4 | AH28: 48.2 | AI28: Yes
A29: T00028 | B29: E0008 | C29: Birmingham | D29: Tax & Legal | E29: Manager | F29: Client meeting | G29: 46188 | H29: 46222 | I29: 46224 | J29: 2026-07 | K29: Birmingham | L29: Zurich | M29: International | N29: Air | O29: 3192 | P29: 34 | Q29: TMC Assisted | R29: A04 | S29: H02 | T29: 296.59 | U29: 0 | V29: 1 | W29: 135 | X29: 133.91 | Y29: 565.5 | Z29: No | AA29: No | AB29: =SUMIF('Trip Changes'!$B:$B,A29,'Trip Changes'!$E:$E) -> 0 | AC29: =SUMIF('Trip Cancellations'!$B:$B,A29,'Trip Cancellations'!$E:$E) -> 0 | AD29: =SUMIF('Trip Cancellations'!$B:$B,A29,'Trip Cancellations'!$F:$F) -> 0 | AE29: =Y29+AB29+AC29-AD29 -> 565.5 | AF29: Yes | AG29: 4 | AH29: 478.8 | AI29: No
A30: T00029 | B30: E0008 | C30: Birmingham | D30: Tax & Legal | E30: Manager | F30: Recruitment / Interview | G30: 46145 | H30: 46178 | I30: 46183 | J30: 2026-06 | K30: Birmingham | L30: Paris | M30: International | N30: Air | O30: 1044 | P30: 33 | Q30: TMC Assisted | R30: A01 | S30: H01 | T30: 361.93 | U30: 0 | V30: 4 | W30: 676.04 | X30: 52.59 | Y30: 1090.56 | Z30: No | AA30: No | AB30: =SUMIF('Trip Changes'!$B:$B,A30,'Trip Changes'!$E:$E) -> 0 | AC30: =SUMIF('Trip Cancellations'!$B:$B,A30,'Trip Cancellations'!$E:$E) -> 0 | AD30: =SUMIF('Trip Cancellations'!$B:$B,A30,'Trip Cancellations'!$F:$F) -> 0 | AE30: =Y30+AB30+AC30-AD30 -> 1090.56 | AF30: Yes | AG30: 4 | AH30: 156.6 | AI30: No
A31: T00030 | B31: E0008 | C31: Birmingham | D31: Tax & Legal | E31: Manager | F31: Project work | G31: 46179 | H31: 46194 | I31: 46195 | J31: 2026-06 | K31: Birmingham | L31: Glasgow | M31: Domestic | N31: Air | O31: 520 | P31: 15 | Q31: Online Booking Tool | R31: A02 | T31: 278.28 | U31: 0 | V31: 0 | W31: 0 | X31: 67.19 | Y31: 345.47 | Z31: No | AA31: No | AB31: =SUMIF('Trip Changes'!$B:$B,A31,'Trip Changes'!$E:$E) -> 0 | AC31: =SUMIF('Trip Cancellations'!$B:$B,A31,'Trip Cancellations'!$E:$E) -> 0 | AD31: =SUMIF('Trip Cancellations'!$B:$B,A31,'Trip Cancellations'!$F:$F) -> 0 | AE31: =Y31+AB31+AC31-AD31 -> 345.47 | AF31: Yes | AG31: 5 | AH31: 78 | AI31: No
A32: T00031 | B32: E0008 | C32: Birmingham | D32: Tax & Legal | E32: Manager | F32: Client meeting | G32: 46200 | H32: 46201 | I32: 46205 | J32: 2026-06 | K32: Birmingham | L32: Amsterdam | M32: International | N32: Air | O32: 3558 | P32: 1 | Q32: Online Booking Tool | R32: A03 | S32: H02 | T32: 177 | U32: 0 | V32: 3 | W32: 423 | X32: 71.71 | Y32: 671.71 | Z32: No | AA32: No | AB32: =SUMIF('Trip Changes'!$B:$B,A32,'Trip Changes'!$E:$E) -> 0 | AC32: =SUMIF('Trip Cancellations'!$B:$B,A32,'Trip Cancellations'!$E:$E) -> 0 | AD32: =SUMIF('Trip Cancellations'!$B:$B,A32,'Trip Cancellations'!$F:$F) -> 0 | AE32: =Y32+AB32+AC32-AD32 -> 671.71 | AF32: No | AG32: 3 | AH32: 533.7 | AI32: No
A33: T00032 | B33: E0009 | C33: Birmingham | D33: Audit & Assurance | E33: Manager | F33: Project work | G33: 46190 | H33: 46206 | I33: 46209 | J33: 2026-07 | K33: Birmingham | L33: Munich | M33: International | N33: Air | O33: 3384 | P33: 16 | Q33: Online Booking Tool | R33: A01 | S33: H04 | T33: 399.57 | U33: 0 | V33: 2 | W33: 318.67 | X33: 73.68 | Y33: 791.92 | Z33: No | AA33: No | AB33: =SUMIF('Trip Changes'!$B:$B,A33,'Trip Changes'!$E:$E) -> 0 | AC33: =SUMIF('Trip Cancellations'!$B:$B,A33,'Trip Cancellations'!$E:$E) -> 0 | AD33: =SUMIF('Trip Cancellations'!$B:$B,A33,'Trip Cancellations'!$F:$F) -> 0 | AE33: =Y33+AB33+AC33-AD33 -> 791.92 | AF33: Yes | AG33: 5 | AH33: 507.6 | AI33: Yes
A34: T00033 | B34: E0009 | C34: Birmingham | D34: Audit & Assurance | E34: Manager | F34: Other | G34: 46166 | H34: 46169 | I34: 46178 | J34: 2026-05 | K34: Birmingham | L34: Singapore | M34: International | N34: Air | O34: 16768 | P34: 3 | Q34: Online Booking Tool | R34: A01 | S34: H05 | T34: 1614.2 | U34: 0 | V34: 8 | W34: 1617.35 | X34: 66.93 | Y34: 3298.48 | Z34: Yes | AA34: No | AB34: =SUMIF('Trip Changes'!$B:$B,A34,'Trip Changes'!$E:$E) -> 68.12 | AC34: =SUMIF('Trip Cancellations'!$B:$B,A34,'Trip Cancellations'!$E:$E) -> 0 | AD34: =SUMIF('Trip Cancellations'!$B:$B,A34,'Trip Cancellations'!$F:$F) -> 0 | AE34: =Y34+AB34+AC34-AD34 -> 3366.6 | AF34: No | AG34: 4 | AH34: 2515.2 | AI34: No
A35: T00034 | B35: E0010 | C35: Aberdeen | D35: Risk Advisory | E35: Manager | F35: Client meeting | G35: 46201 | H35: 46206 | I35: 46208 | J35: 2026-07 | K35: Aberdeen | L35: Brussels | M35: International | N35: Air | O35: 2394 | P35: 5 | Q35: Online Booking Tool | R35: A03 | S35: H01 | T35: 610.39 | U35: 0 | V35: 1 | W35: 246.82 | X35: 77.77 | Y35: 934.98 | Z35: Yes | AA35: No | AB35: =SUMIF('Trip Changes'!$B:$B,A35,'Trip Changes'!$E:$E) -> 173.75 | AC35: =SUMIF('Trip Cancellations'!$B:$B,A35,'Trip Cancellations'!$E:$E) -> 0 | AD35: =SUMIF('Trip Cancellations'!$B:$B,A35,'Trip Cancellations'!$F:$F) -> 0 | AE35: =Y35+AB35+AC35-AD35 -> 1108.73 | AF35: Yes | AG35: 4 | AH35: 359.1 | AI35: Yes
A36: T00035 | B36: E0010 | C36: Aberdeen | D36: Risk Advisory | E36: Manager | F36: Conference / Event | G36: 46194 | H36: 46214 | I36: 46217 | J36: 2026-07 | K36: Aberdeen | L36: London | M36: Domestic | N36: Rail | O36: 722 | P36: 20 | Q36: Online Booking Tool | S36: H06 | T36: 0 | U36: 141.66 | V36: 2 | W36: 199.05 | X36: 101.17 | Y36: 441.88 | Z36: No | AA36: No | AB36: =SUMIF('Trip Changes'!$B:$B,A36,'Trip Changes'!$E:$E) -> 0 | AC36: =SUMIF('Trip Cancellations'!$B:$B,A36,'Trip Cancellations'!$E:$E) -> 0 | AD36: =SUMIF('Trip Cancellations'!$B:$B,A36,'Trip Cancellations'!$F:$F) -> 0 | AE36: =Y36+AB36+AC36-AD36 -> 441.88 | AF36: Yes | AG36: 5 | AH36: 28.9 | AI36: No
A37: T00036 | B37: E0010 | C37: Aberdeen | D37: Risk Advisory | E37: Manager | F37: Recruitment / Interview | G37: 46128 | H37: 46152 | I37: 46157 | J37: 2026-05 | K37: Aberdeen | L37: Dublin | M37: International | N37: Air | O37: 1404 | P37: 24 | Q37: Direct Supplier | R37: A01 | S37: H03 | T37: 172.11 | U37: 0 | V37: 4 | W37: 651.55 | X37: 101.25 | Y37: 924.91 | Z37: No | AA37: No | AB37: =SUMIF('Trip Changes'!$B:$B,A37,'Trip Changes'!$E:$E) -> 0 | AC37: =SUMIF('Trip Cancellations'!$B:$B,A37,'Trip Cancellations'!$E:$E) -> 0 | AD37: =SUMIF('Trip Cancellations'!$B:$B,A37,'Trip Cancellations'!$F:$F) -> 0 | AE37: =Y37+AB37+AC37-AD37 -> 924.91 | AF37: Yes | AG37: 4 | AH37: 210.6 | AI37: No
A38: T00037 | B38: E0010 | C38: Aberdeen | D38: Risk Advisory | E38: Manager | F38: Internal meeting | G38: 46145 | H38: 46147 | I38: 46150 | J38: 2026-05 | K38: Aberdeen | L38: Dublin | M38: International | N38: Air | O38: 2610 | P38: 2 | Q38: Online Booking Tool | R38: A10 | S38: H01 | T38: 448.21 | U38: 0 | V38: 2 | W38: 357.67 | X38: 68 | Y38: 873.88 | Z38: No | AA38: No | AB38: =SUMIF('Trip Changes'!$B:$B,A38,'Trip Changes'!$E:$E) -> 0 | AC38: =SUMIF('Trip Cancellations'!$B:$B,A38,'Trip Cancellations'!$E:$E) -> 0 | AD38: =SUMIF('Trip Cancellations'!$B:$B,A38,'Trip Cancellations'!$F:$F) -> 0 | AE38: =Y38+AB38+AC38-AD38 -> 873.88 | AF38: Yes | AG38: 4 | AH38: 391.5 | AI38: No
A39: T00038 | B39: E0011 | C39: London | D39: Consulting | E39: Analyst | F39: Project work | G39: 46180 | H39: 46201 | I39: 46203 | J39: 2026-06 | K39: London | L39: Milan | M39: International | N39: Air | O39: 3134 | P39: 21 | Q39: TMC Assisted | R39: A01 | S39: H03 | T39: 454.32 | U39: 0 | V39: 1 | W39: 170.76 | X39: 36.17 | Y39: 661.25 | Z39: No | AA39: Yes | AB39: =SUMIF('Trip Changes'!$B:$B,A39,'Trip Changes'!$E:$E) -> 0 | AC39: =SUMIF('Trip Cancellations'!$B:$B,A39,'Trip Cancellations'!$E:$E) -> 58.97 | AD39: =SUMIF('Trip Cancellations'!$B:$B,A39,'Trip Cancellations'!$F:$F) -> 312.54 | AE39: =Y39+AB39+AC39-AD39 -> 407.68 | AF39: Yes | AG39: 3 | AH39: 470.1 | AI39: Yes
A40: T00039 | B40: E0011 | C40: London | D40: Consulting | E40: Analyst | F40: Training | G40: 46196 | H40: 46212 | I40: 46215 | J40: 2026-07 | K40: London | L40: New York | M40: International | N40: Air | O40: 10758 | P40: 16 | Q40: TMC Assisted | R40: A07 | S40: H05 | T40: 1112.13 | U40: 0 | V40: 2 | W40: 450.96 | X40: 68.89 | Y40: 1631.98 | Z40: Yes | AA40: No | AB40: =SUMIF('Trip Changes'!$B:$B,A40,'Trip Changes'!$E:$E) -> 31.77 | AC40: =SUMIF('Trip Cancellations'!$B:$B,A40,'Trip Cancellations'!$E:$E) -> 0 | AD40: =SUMIF('Trip Cancellations'!$B:$B,A40,'Trip Cancellations'!$F:$F) -> 0 | AE40: =Y40+AB40+AC40-AD40 -> 1663.75 | AF40: Yes | AG40: 3 | AH40: 1613.7 | AI40: Yes
...

Sheet Trips_Workbook
A1: trip_id | B1: employee_id | C1: home_office | D1: department | E1: grade | F1: trip_purpose | G1: booking_date | H1: departure_date | I1: return_date | J1: travel_month | K1: origin | L1: destination | M1: trip_type | N1: travel_mode | O1: travel_class | P1: distance_km | Q1: booking_lead_days | R1: booking_lead_bucket | S1: booking_channel | T1: airline_id | U1: hotel_id | V1: hotel_name | W1: airfare_gbp | X1: rail_cost_gbp | Y1: hotel_nights | Z1: hotel_cost_per_night | AA1: hotel_cost_gbp | AB1: ground_transport_gbp | AC1: original_trip_cost_gbp | AD1: changed_value_check | AE1: cancelled_value_check | AF1: total_change_cost_gbp | AG1: total_cancellation_fee_gbp | AH1: refund_received_gbp | AI1: final_trip_cost_gbp | AJ1: hotel_rate_compliant_calc | AK1: hotel_supplier_compliant_calc | AL1: airline_compliant_calc | AM1: class_compliant_calc | AN1: channel_compliant_calc | AO1: supplier_compliant_calc | AP1: policy_compliant_value_check | AQ1: policy_compliant_calc | AR1: csat_score_check | AS1: co2_kg | AT1: airline_name | AU1: hotel_name2 | AV1: feedback_submitted | AW1: missing_required_data | AX1: date_check | AY1: lead_time_check | AZ1: original_cost_check | BA1: final_cost_check | BB1: change_records_check | BC1: changed_flag_check | BD1: changed | BE1: cancelled | BF1: policy_compliant | BG1: feedback_submitted_check | BH1: csat_score | BI1: travel_mode | BJ1: trip_type | BK1: booking_channel
A2: T00001 | B2: E0001 | C2: Aberdeen | D2: Technology | E2: Senior Manager | F2: Client meeting | G2: 46176 | H2: 46189 | I2: 46192 | J2: 2026-06 | K2: Aberdeen | L2: Manchester | M2: Domestic | N2: Rail | O2: Standard / 2nd Class | P2: 1010 | Q2: 13 | R2: =IF(Q2<=3,"0-3 days",IF(Q2<=7,"4-7 days",IF(Q2<=14,"8-14 days",IF(Q2<=30,"15-30 days","31+ days")))) -> 8-14 days | S2: Online Booking Tool | U2: H06 | V2: =IF(U2="","",IFERROR(VLOOKUP(U2,Hotels!A:B,2,FALSE),"Not Found")) -> Premier Inn | W2: 0 | X2: 182.55 | Y2: 2 | Z2: =IF(Y2>0,AA2/Y2,0) -> 163.835 | AA2: 327.67 | AB2: 56.62 | AC2: 566.84 | AD2: No | AE2: No | AF2: =SUMIF('Trip Changes'!$B:$B,A2,'Trip Changes'!$E:$E) -> 0 | AG2: =SUMIF('Trip Cancellations'!$B:$B,A2,'Trip Cancellations'!$E:$E) -> 0 | AH2: =SUMIF('Trip Cancellations'!$B:$B,A2,'Trip Cancellations'!$F:$F) -> 0 | AI2: =AC2+AF2+AG2-AH2 -> 566.84 | AJ2: =IF(Y2=0,"N/A", IF(OR(L2="London",L2="Manchester",L2="Birmingham",L2="Edinburgh",L2="Glasgow", L2="New York",L2="Boston",L2="Chicago",L2="Zurich",L2="Singapore",L2="Hong Kong",L2="Dubai"), IF(Z2<=220,"Yes","No"), IF(Z2<=180,"Yes","No"))) -> Yes | AK2: =IF(Y2=0,"N/A", IF(_xlfn.XLOOKUP(U2,Hotels!A:A,Hotels!C:C)=TRUE,"Yes","No")) -> Yes | AL2: =IF(N2="Rail","N/A",IF(_xlfn.XLOOKUP(T2,Airlines!A:A,Airlines!C:C)=TRUE,"Yes","No")) -> N/A | AM2: =IF(OR( AND(N2="Air",O2="Economy"), AND(N2="Rail",O2="Standard / 2nd Class") ),"Yes","No") -> Yes | AN2: =IF(OR(S2="Online Booking Tool",S2="TMC Assisted"),"Yes","No") -> Yes | AO2: =IF(AND(OR(AK2="Yes",AK2="N/A"),OR(AL2="Yes",AL2="N/A")),"Yes","No") -> Yes | AP2: Yes | AQ2: =IF(AND(OR(AJ2="Yes",AJ2="N/A"),OR(AK2="Yes",AK2="N/A"),OR(AL2="Yes",AL2="N/A"),AM2="Yes",AN2="Yes"),"Yes","No") -> Yes | AR2: 5 | AS2: 40.4 | AT2: =IF(T2="","",_xlfn.XLOOKUP(T2,Airlines!A:A,Airlines!B:B,"Not Found")) | AU2: =IF(U2="","",_xlfn.XLOOKUP(U2,Hotels!A:A,Hotels!B:B,"Not found")) -> Premier Inn | AV2: Yes | AW2: =IF(OR(A2="",B2="",G2="",H2="",I2="",K2="",L2="",M2="",N2="",S2="",AC2="",AI2=""),"Check","OK") -> OK | AX2: =IF(AND(G2<=H2, H2<=I2),"OK","CHECK") -> OK | AY2: =IF(Q2=H2-G2,"OK","Check") -> OK | AZ2: =IF(ROUND(W2+X2+AA2+AB2,2)=ROUND(AC2,2),"OK","Check") -> OK | BA2: =IF(ROUND(AC2+AF2+AG2-AH2,2)=ROUND(AI2,2),"OK","Check") -> OK | BB2: =COUNTIF('Trip Changes'!B:B,A2) -> 0 | BC2: =IF(OR(AND(AD2="Yes",COUNTIF('Trip Changes'!B:B,A2)>0),AND(AD2="No",COUNTIF('Trip Changes'!B:B,A2)=0)),"OK","Check") -> OK | BD2: =IF(OR(AD2="Yes",AD2="No"),"OK","Check") -> OK | BE2: =IF(OR(AE2="Yes",AE2="No"),"OK","Check") -> OK | BF2: =IF(OR(AP2="Yes",AP2="No"),"OK","Check") -> OK | BG2: =IF(OR(AV2="Yes",AV2="No"),"OK","Check") -> OK | BH2: =IF(AND(ISNUMBER(AR2),AR2>=1,AR2<=5),"OK","Check") -> OK | BI2: =IF(OR(N2="Air",N2="Rail"),"OK","Check") -> OK | BJ2: =IF(OR(M2="Domestic",M2="International"),"OK","Check") -> OK | BK2: =IF(OR(S2="Online Booking Tool",S2="TMC Assisted",S2="Direct Supplier",S2="Other"),"OK","Check") -> OK
A3: T00002 | B3: E0001 | C3: Aberdeen | D3: Technology | E3: Senior Manager | F3: Client meeting | G3: 46224 | H3: 46226 | I3: 46230 | J3: 2026-07 | K3: Aberdeen | L3: Frankfurt | M3: International | N3: Air | O3: Economy | P3: 1390 | Q3: 2 | R3: =IF(Q3<=3,"0-3 days",IF(Q3<=7,"4-7 days",IF(Q3<=14,"8-14 days",IF(Q3<=30,"15-30 days","31+ days")))) -> 0-3 days | S3: Online Booking Tool | T3: A01 | U3: H02 | V3: =IF(U3="","",IFERROR(VLOOKUP(U3,Hotels!A:B,2,FALSE),"Not Found")) -> Hilton | W3: 480.08 | X3: 0 | Y3: 3 | Z3: =IF(Y3>0,AA3/Y3,0) -> 187.09 | AA3: 561.27 | AB3: 59 | AC3: 1100.35 | AD3: No | AE3: No | AF3: =SUMIF('Trip Changes'!$B:$B,A3,'Trip Changes'!$E:$E) -> 0 | AG3: =SUMIF('Trip Cancellations'!$B:$B,A3,'Trip Cancellations'!$E:$E) -> 0 | AH3: =SUMIF('Trip Cancellations'!$B:$B,A3,'Trip Cancellations'!$F:$F) -> 0 | AI3: =AC3+AF3+AG3-AH3 -> 1100.35 | AJ3: =IF(Y3=0,"N/A", IF(OR(L3="London",L3="Manchester",L3="Birmingham",L3="Edinburgh",L3="Glasgow", L3="New York",L3="Boston",L3="Chicago",L3="Zurich",L3="Singapore",L3="Hong Kong",L3="Dubai"), IF(Z3<=220,"Yes","No"), IF(Z3<=180,"Yes","No"))) -> No | AK3: =IF(Y3=0,"N/A", IF(_xlfn.XLOOKUP(U3,Hotels!A:A,Hotels!C:C)=TRUE,"Yes","No")) -> Yes | AL3: =IF(N3="Rail","N/A",IF(_xlfn.XLOOKUP(T3,Airlines!A:A,Airlines!C:C)=TRUE,"Yes","No")) -> Yes | AM3: =IF(OR( AND(N3="Air",O3="Economy"), AND(N3="Rail",O3="Standard / 2nd Class") ),"Yes","No") -> Yes | AN3: =IF(OR(S3="Online Booking Tool",S3="TMC Assisted"),"Yes","No") -> Yes | AO3: =IF(AND(OR(AK3="Yes",AK3="N/A"),OR(AL3="Yes",AL3="N/A")),"Yes","No") -> Yes | AP3: Yes | AQ3: =IF(AND(OR(AJ3="Yes",AJ3="N/A"),OR(AK3="Yes",AK3="N/A"),OR(AL3="Yes",AL3="N/A"),AM3="Yes",AN3="Yes"),"Yes","No") -> No | AR3: 4 | AS3: 208.5 | AT3: =IF(T3="","",_xlfn.XLOOKUP(T3,Airlines!A:A,Airlines!B:B,"Not Found")) -> British Airways | AU3: =IF(U3="","",_xlfn.XLOOKUP(U3,Hotels!A:A,Hotels!B:B,"Not found")) -> Hilton | AV3: No | AW3: =IF(OR(A3="",B3="",G3="",H3="",I3="",K3="",L3="",M3="",N3="",S3="",AC3="",AI3=""),"Check","OK") -> OK | AX3: =IF(AND(G3<=H3, H3<=I3),"OK","CHECK") -> OK | AY3: =IF(Q3=H3-G3,"OK","Check") -> OK | AZ3: =IF(ROUND(W3+X3+AA3+AB3,2)=ROUND(AC3,2),"OK","Check") -> OK | BA3: =IF(ROUND(AC3+AF3+AG3-AH3,2)=ROUND(AI3,2),"OK","Check") -> OK | BB3: =COUNTIF('Trip Changes'!B:B,A3) -> 0 | BC3: =IF(OR(AND(AD3="Yes",COUNTIF('Trip Changes'!B:B,A3)>0),AND(AD3="No",COUNTIF('Trip Changes'!B:B,A3)=0)),"OK","Check") -> OK | BD3: =IF(OR(AD3="Yes",AD3="No"),"OK","Check") -> OK | BE3: =IF(OR(AE3="Yes",AE3="No"),"OK","Check") -> OK | BF3: =IF(OR(AP3="Yes",AP3="No"),"OK","Check") -> OK | BG3: =IF(OR(AV3="Yes",AV3="No"),"OK","Check") -> OK | BH3: =IF(AND(ISNUMBER(AR3),AR3>=1,AR3<=5),"OK","Check") -> OK | BI3: =IF(OR(N3="Air",N3="Rail"),"OK","Check") -> OK | BJ3: =IF(OR(M3="Domestic",M3="International"),"OK","Check") -> OK | BK3: =IF(OR(S3="Online Booking Tool",S3="TMC Assisted",S3="Direct Supplier",S3="Other"),"OK","Check") -> OK
A4: T00003 | B4: E0001 | C4: Aberdeen | D4: Technology | E4: Senior Manager | F4: Internal meeting | G4: 46169 | H4: 46178 | I4: 46182 | J4: 2026-06 | K4: Aberdeen | L4: Milan | M4: International | N4: Air | O4: Economy | P4: 1900 | Q4: 9 | R4: =IF(Q4<=3,"0-3 days",IF(Q4<=7,"4-7 days",IF(Q4<=14,"8-14 days",IF(Q4<=30,"15-30 days","31+ days")))) -> 8-14 days | S4: TMC Assisted | T4: A05 | U4: H02 | V4: =IF(U4="","",IFERROR(VLOOKUP(U4,Hotels!A:B,2,FALSE),"Not Found")) -> Hilton | W4: 416.18 | X4: 0 | Y4: 3 | Z4: =IF(Y4>0,AA4/Y4,0) -> 212.52 | AA4: 637.56 | AB4: 140.94 | AC4: 1194.68 | AD4: No | AE4: No | AF4: =SUMIF('Trip Changes'!$B:$B,A4,'Trip Changes'!$E:$E) -> 0 | AG4: =SUMIF('Trip Cancellations'!$B:$B,A4,'Trip Cancellations'!$E:$E) -> 0 | AH4: =SUMIF('Trip Cancellations'!$B:$B,A4,'Trip Cancellations'!$F:$F) -> 0 | AI4: =AC4+AF4+AG4-AH4 -> 1194.68 | AJ4: =IF(Y4=0,"N/A", IF(OR(L4="London",L4="Manchester",L4="Birmingham",L4="Edinburgh",L4="Glasgow", L4="New York",L4="Boston",L4="Chicago",L4="Zurich",L4="Singapore",L4="Hong Kong",L4="Dubai"), IF(Z4<=220,"Yes","No"), IF(Z4<=180,"Yes","No"))) -> No | AK4: =IF(Y4=0,"N/A", IF(_xlfn.XLOOKUP(U4,Hotels!A:A,Hotels!C:C)=TRUE,"Yes","No")) -> Yes | AL4: =IF(N4="Rail","N/A",IF(_xlfn.XLOOKUP(T4,Airlines!A:A,Airlines!C:C)=TRUE,"Yes","No")) -> Yes | AM4: =IF(OR( AND(N4="Air",O4="Economy"), AND(N4="Rail",O4="Standard / 2nd Class") ),"Yes","No") -> Yes | AN4: =IF(OR(S4="Online Booking Tool",S4="TMC Assisted"),"Yes","No") -> Yes | AO4: =IF(AND(OR(AK4="Yes",AK4="N/A"),OR(AL4="Yes",AL4="N/A")),"Yes","No") -> Yes | AP4: Yes | AQ4: =IF(AND(OR(AJ4="Yes",AJ4="N/A"),OR(AK4="Yes",AK4="N/A"),OR(AL4="Yes",AL4="N/A"),AM4="Yes",AN4="Yes"),"Yes","No") -> No | AR4: 5 | AS4: 285 | AT4: =IF(T4="","",_xlfn.XLOOKUP(T4,Airlines!A:A,Airlines!B:B,"Not Found")) -> Air France | AU4: =IF(U4="","",_xlfn.XLOOKUP(U4,Hotels!A:A,Hotels!B:B,"Not found")) -> Hilton | AV4: Yes | AW4: =IF(OR(A4="",B4="",G4="",H4="",I4="",K4="",L4="",M4="",N4="",S4="",AC4="",AI4=""),"Check","OK") -> OK | AX4: =IF(AND(G4<=H4, H4<=I4),"OK","CHECK") -> OK | AY4: =IF(Q4=H4-G4,"OK","Check") -> OK | AZ4: =IF(ROUND(W4+X4+AA4+AB4,2)=ROUND(AC4,2),"OK","Check") -> OK | BA4: =IF(ROUND(AC4+AF4+AG4-AH4,2)=ROUND(AI4,2),"OK","Check") -> OK | BB4: =COUNTIF('Trip Changes'!B:B,A4) -> 0 | BC4: =IF(OR(AND(AD4="Yes",COUNTIF('Trip Changes'!B:B,A4)>0),AND(AD4="No",COUNTIF('Trip Changes'!B:B,A4)=0)),"OK","Check") -> OK | BD4: =IF(OR(AD4="Yes",AD4="No"),"OK","Check") -> OK | BE4: =IF(OR(AE4="Yes",AE4="No"),"OK","Check") -> OK | BF4: =IF(OR(AP4="Yes",AP4="No"),"OK","Check") -> OK | BG4: =IF(OR(AV4="Yes",AV4="No"),"OK","Check") -> OK | BH4: =IF(AND(ISNUMBER(AR4),AR4>=1,AR4<=5),"OK","Check") -> OK | BI4: =IF(OR(N4="Air",N4="Rail"),"OK","Check") -> OK | BJ4: =IF(OR(M4="Domestic",M4="International"),"OK","Check") -> OK | BK4: =IF(OR(S4="Online Booking Tool",S4="TMC Assisted",S4="Direct Supplier",S4="Other"),"OK","Check") -> OK
A5: T00004 | B5: E0001 | C5: Aberdeen | D5: Technology | E5: Senior Manager | F5: Project work | G5: 46139 | H5: 46153 | I5: 46155 | J5: 2026-05 | K5: Aberdeen | L5: Frankfurt | M5: International | N5: Air | O5: Economy | P5: 1676 | Q5: 14 | R5: =IF(Q5<=3,"0-3 days",IF(Q5<=7,"4-7 days",IF(Q5<=14,"8-14 days",IF(Q5<=30,"15-30 days","31+ days")))) -> 8-14 days | S5: Online Booking Tool | T5: A01 | U5: H01 | V5: =IF(U5="","",IFERROR(VLOOKUP(U5,Hotels!A:B,2,FALSE),"Not Found")) -> Marriott | W5: 261.15 | X5: 0 | Y5: 1 | Z5: =IF(Y5>0,AA5/Y5,0) -> 267.93 | AA5: 267.93 | AB5: 132.51 | AC5: 661.59 | AD5: No | AE5: No | AF5: =SUMIF('Trip Changes'!$B:$B,A5,'Trip Changes'!$E:$E) -> 0 | AG5: =SUMIF('Trip Cancellations'!$B:$B,A5,'Trip Cancellations'!$E:$E) -> 0 | AH5: =SUMIF('Trip Cancellations'!$B:$B,A5,'Trip Cancellations'!$F:$F) -> 0 | AI5: =AC5+AF5+AG5-AH5 -> 661.59 | AJ5: =IF(Y5=0,"N/A", IF(OR(L5="London",L5="Manchester",L5="Birmingham",L5="Edinburgh",L5="Glasgow", L5="New York",L5="Boston",L5="Chicago",L5="Zurich",L5="Singapore",L5="Hong Kong",L5="Dubai"), IF(Z5<=220,"Yes","No"), IF(Z5<=180,"Yes","No"))) -> No | AK5: =IF(Y5=0,"N/A", IF(_xlfn.XLOOKUP(U5,Hotels!A:A,Hotels!C:C)=TRUE,"Yes","No")) -> Yes | AL5: =IF(N5="Rail","N/A",IF(_xlfn.XLOOKUP(T5,Airlines!A:A,Airlines!C:C)=TRUE,"Yes","No")) -> Yes | AM5: =IF(OR( AND(N5="Air",O5="Economy"), AND(N5="Rail",O5="Standard / 2nd Class") ),"Yes","No") -> Yes | AN5: =IF(OR(S5="Online Booking Tool",S5="TMC Assisted"),"Yes","No") -> Yes | AO5: =IF(AND(OR(AK5="Yes",AK5="N/A"),OR(AL5="Yes",AL5="N/A")),"Yes","No") -> Yes | AP5: Yes | AQ5: =IF(AND(OR(AJ5="Yes",AJ5="N/A"),OR(AK5="Yes",AK5="N/A"),OR(AL5="Yes",AL5="N/A"),AM5="Yes",AN5="Yes"),"Yes","No") -> No | AR5: 4 | AS5: 251.4 | AT5: =IF(T5="","",_xlfn.XLOOKUP(T5,Airlines!A:A,Airlines!B:B,"Not Found")) -> British Airways | AU5: =IF(U5="","",_xlfn.XLOOKUP(U5,Hotels!A:A,Hotels!B:B,"Not found")) -> Marriott | AV5: No | AW5: =IF(OR(A5="",B5="",G5="",H5="",I5="",K5="",L5="",M5="",N5="",S5="",AC5="",AI5=""),"Check","OK") -> OK | AX5: =IF(AND(G5<=H5, H5<=I5),"OK","CHECK") -> OK | AY5: =IF(Q5=H5-G5,"OK","Check") -> OK | AZ5: =IF(ROUND(W5+X5+AA5+AB5,2)=ROUND(AC5,2),"OK","Check") -> OK | BA5: =IF(ROUND(AC5+AF5+AG5-AH5,2)=ROUND(AI5,2),"OK","Check") -> OK | BB5: =COUNTIF('Trip Changes'!B:B,A5) -> 0 | BC5: =IF(OR(AND(AD5="Yes",COUNTIF('Trip Changes'!B:B,A5)>0),AND(AD5="No",COUNTIF('Trip Changes'!B:B,A5)=0)),"OK","Check") -> OK | BD5: =IF(OR(AD5="Yes",AD5="No"),"OK","Check") -> OK | BE5: =IF(OR(AE5="Yes",AE5="No"),"OK","Check") -> OK | BF5: =IF(OR(AP5="Yes",AP5="No"),"OK","Check") -> OK | BG5: =IF(OR(AV5="Yes",AV5="No"),"OK","Check") -> OK | BH5: =IF(AND(ISNUMBER(AR5),AR5>=1,AR5<=5),"OK","Check") -> OK | BI5: =IF(OR(N5="Air",N5="Rail"),"OK","Check") -> OK | BJ5: =IF(OR(M5="Domestic",M5="International"),"OK","Check") -> OK | BK5: =IF(OR(S5="Online Booking Tool",S5="TMC Assisted",S5="Direct Supplier",S5="Other"),"OK","Check") -> OK
A6: T00005 | B6: E0002 | C6: Reading | D6: Audit & Assurance | E6: Manager | F6: Conference / Event | G6: 46114 | H6: 46146 | I6: 46149 | J6: 2026-05 | K6: Reading | L6: Berlin | M6: International | N6: Air | O6: Economy | P6: 1146 | Q6: 32 | R6: =IF(Q6<=3,"0-3 days",IF(Q6<=7,"4-7 days",IF(Q6<=14,"8-14 days",IF(Q6<=30,"15-30 days","31+ days")))) -> 31+ days | S6: TMC Assisted | T6: A04 | U6: H04 | V6: =IF(U6="","",IFERROR(VLOOKUP(U6,Hotels!A:B,2,FALSE),"Not Found")) -> Accor | W6: 502.93 | X6: 0 | Y6: 2 | Z6: =IF(Y6>0,AA6/Y6,0) -> 138.55 | AA6: 277.1 | AB6: 65.55 | AC6: 845.58 | AD6: No | AE6: No | AF6: =SUMIF('Trip Changes'!$B:$B,A6,'Trip Changes'!$E:$E) -> 0 | AG6: =SUMIF('Trip Cancellations'!$B:$B,A6,'Trip Cancellations'!$E:$E) -> 0 | AH6: =SUMIF('Trip Cancellations'!$B:$B,A6,'Trip Cancellations'!$F:$F) -> 0 | AI6: =AC6+AF6+AG6-AH6 -> 845.58 | AJ6: =IF(Y6=0,"N/A", IF(OR(L6="London",L6="Manchester",L6="Birmingham",L6="Edinburgh",L6="Glasgow", L6="New York",L6="Boston",L6="Chicago",L6="Zurich",L6="Singapore",L6="Hong Kong",L6="Dubai"), IF(Z6<=220,"Yes","No"), IF(Z6<=180,"Yes","No"))) -> Yes | AK6: =IF(Y6=0,"N/A", IF(_xlfn.XLOOKUP(U6,Hotels!A:A,Hotels!C:C)=TRUE,"Yes","No")) -> Yes | AL6: =IF(N6="Rail","N/A",IF(_xlfn.XLOOKUP(T6,Airlines!A:A,Airlines!C:C)=TRUE,"Yes","No")) -> Yes | AM6: =IF(OR( AND(N6="Air",O6="Economy"), AND(N6="Rail",O6="Standard / 2nd Class") ),"Yes","No") -> Yes | AN6: =IF(OR(S6="Online Booking Tool",S6="TMC Assisted"),"Yes","No") -> Yes | AO6: =IF(AND(OR(AK6="Yes",AK6="N/A"),OR(AL6="Yes",AL6="N/A")),"Yes","No") -> Yes | AP6: Yes | AQ6: =IF(AND(OR(AJ6="Yes",AJ6="N/A"),OR(AK6="Yes",AK6="N/A"),OR(AL6="Yes",AL6="N/A"),AM6="Yes",AN6="Yes"),"Yes","No") -> Yes | AR6: 5 | AS6: 171.9 | AT6: =IF(T6="","",_xlfn.XLOOKUP(T6,Airlines!A:A,Airlines!B:B,"Not Found")) -> Lufthansa | AU6: =IF(U6="","",_xlfn.XLOOKUP(U6,Hotels!A:A,Hotels!B:B,"Not found")) -> Accor | AV6: No | AW6: =IF(OR(A6="",B6="",G6="",H6="",I6="",K6="",L6="",M6="",N6="",S6="",AC6="",AI6=""),"Check","OK") -> OK | AX6: =IF(AND(G6<=H6, H6<=I6),"OK","CHECK") -> OK | AY6: =IF(Q6=H6-G6,"OK","Check") -> OK | AZ6: =IF(ROUND(W6+X6+AA6+AB6,2)=ROUND(AC6,2),"OK","Check") -> OK | BA6: =IF(ROUND(AC6+AF6+AG6-AH6,2)=ROUND(AI6,2),"OK","Check") -> OK | BB6: =COUNTIF('Trip Changes'!B:B,A6) -> 0 | BC6: =IF(OR(AND(AD6="Yes",COUNTIF('Trip Changes'!B:B,A6)>0),AND(AD6="No",COUNTIF('Trip Changes'!B:B,A6)=0)),"OK","Check") -> OK | BD6: =IF(OR(AD6="Yes",AD6="No"),"OK","Check") -> OK | BE6: =IF(OR(AE6="Yes",AE6="No"),"OK","Check") -> OK | BF6: =IF(OR(AP6="Yes",AP6="No"),"OK","Check") -> OK | BG6: =IF(OR(AV6="Yes",AV6="No"),"OK","Check") -> OK | BH6: =IF(AND(ISNUMBER(AR6),AR6>=1,AR6<=5),"OK","Check") -> OK | BI6: =IF(OR(N6="Air",N6="Rail"),"OK","Check") -> OK | BJ6: =IF(OR(M6="Domestic",M6="International"),"OK","Check") -> OK | BK6: =IF(OR(S6="Online Booking Tool",S6="TMC Assisted",S6="Direct Supplier",S6="Other"),"OK","Check") -> OK
A7: T00006 | B7: E0002 | C7: Reading | D7: Audit & Assurance | E7: Manager | F7: Client meeting | G7: 46153 | H7: 46170 | I7: 46174 | J7: 2026-05 | K7: Reading | L7: Zurich | M7: International | N7: Air | O7: Economy | P7: 2472 | Q7: 17 | R7: =IF(Q7<=3,"0-3 days",IF(Q7<=7,"4-7 days",IF(Q7<=14,"8-14 days",IF(Q7<=30,"15-30 days","31+ days")))) -> 15-30 days | S7: Online Booking Tool | T7: A02 | U7: H02 | V7: =IF(U7="","",IFERROR(VLOOKUP(U7,Hotels!A:B,2,FALSE),"Not Found")) -> Hilton | W7: 150 | X7: 0 | Y7: 3 | Z7: =IF(Y7>0,AA7/Y7,0) -> 152.62667 | AA7: 457.88 | AB7: 45.91 | AC7: 653.79 | AD7: No | AE7: No | AF7: =SUMIF('Trip Changes'!$B:$B,A7,'Trip Changes'!$E:$E) -> 0 | AG7: =SUMIF('Trip Cancellations'!$B:$B,A7,'Trip Cancellations'!$E:$E) -> 0 | AH7: =SUMIF('Trip Cancellations'!$B:$B,A7,'Trip Cancellations'!$F:$F) -> 0 | AI7: =AC7+AF7+AG7-AH7 -> 653.79 | AJ7: =IF(Y7=0,"N/A", IF(OR(L7="London",L7="Manchester",L7="Birmingham",L7="Edinburgh",L7="Glasgow", L7="New York",L7="Boston",L7="Chicago",L7="Zurich",L7="Singapore",L7="Hong Kong",L7="Dubai"), IF(Z7<=220,"Yes","No"), IF(Z7<=180,"Yes","No"))) -> Yes | AK7: =IF(Y7=0,"N/A", IF(_xlfn.XLOOKUP(U7,Hotels!A:A,Hotels!C:C)=TRUE,"Yes","No")) -> Yes | AL7: =IF(N7="Rail","N/A",IF(_xlfn.XLOOKUP(T7,Airlines!A:A,Airlines!C:C)=TRUE,"Yes","No")) -> Yes | AM7: =IF(OR( AND(N7="Air",O7="Economy"), AND(N7="Rail",O7="Standard / 2nd Class") ),"Yes","No") -> Yes | AN7: =IF(OR(S7="Online Booking Tool",S7="TMC Assisted"),"Yes","No") -> Yes | AO7: =IF(AND(OR(AK7="Yes",AK7="N/A"),OR(AL7="Yes",AL7="N/A")),"Yes","No") -> Yes | AP7: Yes | AQ7: =IF(AND(OR(AJ7="Yes",AJ7="N/A"),OR(AK7="Yes",AK7="N/A"),OR(AL7="Yes",AL7="N/A"),AM7="Yes",AN7="Yes"),"Yes","No") -> Yes | AR7: 5 | AS7: 370.8 | AT7: =IF(T7="","",_xlfn.XLOOKUP(T7,Airlines!A:A,Airlines!B:B,"Not Found")) -> easyJet | AU7: =IF(U7="","",_xlfn.XLOOKUP(U7,Hotels!A:A,Hotels!B:B,"Not found")) -> Hilton | AV7: No | AW7: =IF(OR(A7="",B7="",G7="",H7="",I7="",K7="",L7="",M7="",N7="",S7="",AC7="",AI7=""),"Check","OK") -> OK | AX7: =IF(AND(G7<=H7, H7<=I7),"OK","CHECK") -> OK | AY7: =IF(Q7=H7-G7,"OK","Check") -> OK | AZ7: =IF(ROUND(W7+X7+AA7+AB7,2)=ROUND(AC7,2),"OK","Check") -> OK | BA7: =IF(ROUND(AC7+AF7+AG7-AH7,2)=ROUND(AI7,2),"OK","Check") -> OK | BB7: =COUNTIF('Trip Changes'!B:B,A7) -> 0 | BC7: =IF(OR(AND(AD7="Yes",COUNTIF('Trip Changes'!B:B,A7)>0),AND(AD7="No",COUNTIF('Trip Changes'!B:B,A7)=0)),"OK","Check") -> OK | BD7: =IF(OR(AD7="Yes",AD7="No"),"OK","Check") -> OK | BE7: =IF(OR(AE7="Yes",AE7="No"),"OK","Check") -> OK | BF7: =IF(OR(AP7="Yes",AP7="No"),"OK","Check") -> OK | BG7: =IF(OR(AV7="Yes",AV7="No"),"OK","Check") -> OK | BH7: =IF(AND(ISNUMBER(AR7),AR7>=1,AR7<=5),"OK","Check") -> OK | BI7: =IF(OR(N7="Air",N7="Rail"),"OK","Check") -> OK | BJ7: =IF(OR(M7="Domestic",M7="International"),"OK","Check") -> OK | BK7: =IF(OR(S7="Online Booking Tool",S7="TMC Assisted",S7="Direct Supplier",S7="Other"),"OK","Check") -> OK
A8: T00007 | B8: E0002 | C8: Reading | D8: Audit & Assurance | E8: Manager | F8: Team building | G8: 46208 | H8: 46226 | I8: 46231 | J8: 2026-07 | K8: Reading | L8: Dubai | M8: International | N8: Air | O8: Economy | P8: 16462 | Q8: 18 | R8: =IF(Q8<=3,"0-3 days",IF(Q8<=7,"4-7 days",IF(Q8<=14,"8-14 days",IF(Q8<=30,"15-30 days","31+ days")))) -> 15-30 days | S8: TMC Assisted | T8: A01 | U8: H02 | V8: =IF(U8="","",IFERROR(VLOOKUP(U8,Hotels!A:B,2,FALSE),"Not Found")) -> Hilton | W8: 1520.77 | X8: 0 | Y8: 4 | Z8: =IF(Y8>0,AA8/Y8,0) -> 258.375 | AA8: 1033.5 | AB8: 73.48 | AC8: 2627.75 | AD8: No | AE8: No | AF8: =SUMIF('Trip Changes'!$B:$B,A8,'Trip Changes'!$E:$E) -> 0 | AG8: =SUMIF('Trip Cancellations'!$B:$B,A8,'Trip Cancellations'!$E:$E) -> 0 | AH8: =SUMIF('Trip Cancellations'!$B:$B,A8,'Trip Cancellations'!$F:$F) -> 0 | AI8: =AC8+AF8+AG8-AH8 -> 2627.75 | AJ8: =IF(Y8=0,"N/A", IF(OR(L8="London",L8="Manchester",L8="Birmingham",L8="Edinburgh",L8="Glasgow", L8="New York",L8="Boston",L8="Chicago",L8="Zurich",L8="Singapore",L8="Hong Kong",L8="Dubai"), IF(Z8<=220,"Yes","No"), IF(Z8<=180,"Yes","No"))) -> No | AK8: =IF(Y8=0,"N/A", IF(_xlfn.XLOOKUP(U8,Hotels!A:A,Hotels!C:C)=TRUE,"Yes","No")) -> Yes | AL8: =IF(N8="Rail","N/A",IF(_xlfn.XLOOKUP(T8,Airlines!A:A,Airlines!C:C)=TRUE,"Yes","No")) -> Yes | AM8: =IF(OR( AND(N8="Air",O8="Economy"), AND(N8="Rail",O8="Standard / 2nd Class") ),"Yes","No") -> Yes | AN8: =IF(OR(S8="Online Booking Tool",S8="TMC Assisted"),"Yes","No") -> Yes | AO8: =IF(AND(OR(AK8="Yes",AK8="N/A"),OR(AL8="Yes",AL8="N/A")),"Yes","No") -> Yes | AP8: No | AQ8: =IF(AND(OR(AJ8="Yes",AJ8="N/A"),OR(AK8="Yes",AK8="N/A"),OR(AL8="Yes",AL8="N/A"),AM8="Yes",AN8="Yes"),"Yes","No") -> No | AR8: 5 | AS8: 2469.3 | AT8: =IF(T8="","",_xlfn.XLOOKUP(T8,Airlines!A:A,Airlines!B:B,"Not Found")) -> British Airways | AU8: =IF(U8="","",_xlfn.XLOOKUP(U8,Hotels!A:A,Hotels!B:B,"Not found")) -> Hilton | AV8: No | AW8: =IF(OR(A8="",B8="",G8="",H8="",I8="",K8="",L8="",M8="",N8="",S8="",AC8="",AI8=""),"Check","OK") -> OK | AX8: =IF(AND(G8<=H8, H8<=I8),"OK","CHECK") -> OK | AY8: =IF(Q8=H8-G8,"OK","Check") -> OK | AZ8: =IF(ROUND(W8+X8+AA8+AB8,2)=ROUND(AC8,2),"OK","Check") -> OK | BA8: =IF(ROUND(AC8+AF8+AG8-AH8,2)=ROUND(AI8,2),"OK","Check") -> OK | BB8: =COUNTIF('Trip Changes'!B:B,A8) -> 0 | BC8: =IF(OR(AND(AD8="Yes",COUNTIF('Trip Changes'!B:B,A8)>0),AND(AD8="No",COUNTIF('Trip Changes'!B:B,A8)=0)),"OK","Check") -> OK | BD8: =IF(OR(AD8="Yes",AD8="No"),"OK","Check") -> OK | BE8: =IF(OR(AE8="Yes",AE8="No"),"OK","Check") -> OK | BF8: =IF(OR(AP8="Yes",AP8="No"),"OK","Check") -> OK | BG8: =IF(OR(AV8="Yes",AV8="No"),"OK","Check") -> OK | BH8: =IF(AND(ISNUMBER(AR8),AR8>=1,AR8<=5),"OK","Check") -> OK | BI8: =IF(OR(N8="Air",N8="Rail"),"OK","Check") -> OK | BJ8: =IF(OR(M8="Domestic",M8="International"),"OK","Check") -> OK | BK8: =IF(OR(S8="Online Booking Tool",S8="TMC Assisted",S8="Direct Supplier",S8="Other"),"OK","Check") -> OK
A9: T00008 | B9: E0002 | C9: Reading | D9: Audit & Assurance | E9: Manager | F9: Recruitment / Interview | G9: 46193 | H9: 46203 | I9: 46205 | J9: 2026-06 | K9: Reading | L9: London | M9: Domestic | N9: Rail | O9: Standard / 2nd Class | P9: 512 | Q9: 10 | R9: =IF(Q9<=3,"0-3 days",IF(Q9<=7,"4-7 days",IF(Q9<=14,"8-14 days",IF(Q9<=30,"15-30 days","31+ days")))) -> 8-14 days | S9: Online Booking Tool | U9: H02 | V9: =IF(U9="","",IFERROR(VLOOKUP(U9,Hotels!A:B,2,FALSE),"Not Found")) -> Hilton | W9: 0 | X9: 200.83 | Y9: 1 | Z9: =IF(Y9>0,AA9/Y9,0) -> 133.25 | AA9: 133.25 | AB9: 26.45 | AC9: 360.53 | AD9: No | AE9: No | AF9: =SUMIF('Trip Changes'!$B:$B,A9,'Trip Changes'!$E:$E) -> 0 | AG9: =SUMIF('Trip Cancellations'!$B:$B,A9,'Trip Cancellations'!$E:$E) -> 0 | AH9: =SUMIF('Trip Cancellations'!$B:$B,A9,'Trip Cancellations'!$F:$F) -> 0 | AI9: =AC9+AF9+AG9-AH9 -> 360.53 | AJ9: =IF(Y9=0,"N/A", IF(OR(L9="London",L9="Manchester",L9="Birmingham",L9="Edinburgh",L9="Glasgow", L9="New York",L9="Boston",L9="Chicago",L9="Zurich",L9="Singapore",L9="Hong Kong",L9="Dubai"), IF(Z9<=220,"Yes","No"), IF(Z9<=180,"Yes","No"))) -> Yes | AK9: =IF(Y9=0,"N/A", IF(_xlfn.XLOOKUP(U9,Hotels!A:A,Hotels!C:C)=TRUE,"Yes","No")) -> Yes | AL9: =IF(N9="Rail","N/A",IF(_xlfn.XLOOKUP(T9,Airlines!A:A,Airlines!C:C)=TRUE,"Yes","No")) -> N/A | AM9: =IF(OR( AND(N9="Air",O9="Economy"), AND(N9="Rail",O9="Standard / 2nd Class") ),"Yes","No") -> Yes | AN9: =IF(OR(S9="Online Booking Tool",S9="TMC Assisted"),"Yes","No") -> Yes | AO9: =IF(AND(OR(AK9="Yes",AK9="N/A"),OR(AL9="Yes",AL9="N/A")),"Yes","No") -> Yes | AP9: Yes | AQ9: =IF(AND(OR(AJ9="Yes",AJ9="N/A"),OR(AK9="Yes",AK9="N/A"),OR(AL9="Yes",AL9="N/A"),AM9="Yes",AN9="Yes"),"Yes","No") -> Yes | AR9: 4 | AS9: 20.5 | AT9: =IF(T9="","",_xlfn.XLOOKUP(T9,Airlines!A:A,Airlines!B:B,"Not Found")) | AU9: =IF(U9="","",_xlfn.XLOOKUP(U9,Hotels!A:A,Hotels!B:B,"Not found")) -> Hilton | AV9: No | AW9: =IF(OR(A9="",B9="",G9="",H9="",I9="",K9="",L9="",M9="",N9="",S9="",AC9="",AI9=""),"Check","OK") -> OK | AX9: =IF(AND(G9<=H9, H9<=I9),"OK","CHECK") -> OK | AY9: =IF(Q9=H9-G9,"OK","Check") -> OK | AZ9: =IF(ROUND(W9+X9+AA9+AB9,2)=ROUND(AC9,2),"OK","Check") -> OK | BA9: =IF(ROUND(AC9+AF9+AG9-AH9,2)=ROUND(AI9,2),"OK","Check") -> OK | BB9: =COUNTIF('Trip Changes'!B:B,A9) -> 0 | BC9: =IF(OR(AND(AD9="Yes",COUNTIF('Trip Changes'!B:B,A9)>0),AND(AD9="No",COUNTIF('Trip Changes'!B:B,A9)=0)),"OK","Check") -> OK | BD9: =IF(OR(AD9="Yes",AD9="No"),"OK","Check") -> OK | BE9: =IF(OR(AE9="Yes",AE9="No"),"OK","Check") -> OK | BF9: =IF(OR(AP9="Yes",AP9="No"),"OK","Check") -> OK | BG9: =IF(OR(AV9="Yes",AV9="No"),"OK","Check") -> OK | BH9: =IF(AND(ISNUMBER(AR9),AR9>=1,AR9<=5),"OK","Check") -> OK | BI9: =IF(OR(N9="Air",N9="Rail"),"OK","Check") -> OK | BJ9: =IF(OR(M9="Domestic",M9="International"),"OK","Check") -> OK | BK9: =IF(OR(S9="Online Booking Tool",S9="TMC Assisted",S9="Direct Supplier",S9="Other"),"OK","Check") -> OK
